[
  {
    "timestamp": "2025-02-07T16:46:08.878087",
    "error_type": "KeyError",
    "error_message": "'ai'",
    "traceback": "  File \"C:\\Users\\bgund\\OneDrive\\Belgeler\\Projects\\Vscode-Extensions\\computer-assistant\\src\\main.py\", line 12, in <module>\n    main()\n    ~~~~^^\n  File \"C:\\Users\\bgund\\OneDrive\\Belgeler\\Projects\\Vscode-Extensions\\computer-assistant\\src\\gui.py\", line 355, in main\n    window = AICodeEditorGUI()\n  File \"C:\\Users\\bgund\\OneDrive\\Belgeler\\Projects\\Vscode-Extensions\\computer-assistant\\src\\gui.py\", line 62, in __init__\n    self.agent = CodeEditorAgent()\n                 ~~~~~~~~~~~~~~~^^\n  File \"C:\\Users\\bgund\\OneDrive\\Belgeler\\Projects\\Vscode-Extensions\\computer-assistant\\src\\code_agent.py\", line 66, in __init__\n    model_config = self.config_manager.get_model_config()\n  File \"C:\\Users\\bgund\\OneDrive\\Belgeler\\Projects\\Vscode-Extensions\\computer-assistant\\src\\config_manager.py\", line 231, in get_model_config\n    model_name = self.config[\"ai\"][\"default_model\"]\n                 ~~~~~~~~~~~^^^^^^\n",
    "command": "UNCAUGHT_EXCEPTION",
    "context": "Global Exception Handler",
    "stack_info": "  File \"C:\\Users\\bgund\\OneDrive\\Belgeler\\Projects\\Vscode-Extensions\\computer-assistant\\src\\error_handler.py\", line 77, in handle_uncaught_exception\n    'stack_info': ''.join(traceback.format_stack())\n"
  }
]